[2022-07-10 23:00:26,653] {taskinstance.py:896} INFO - Dependencies all met for <TaskInstance: assignment.task_one 2022-07-09T00:00:00+00:00 [queued]>
[2022-07-10 23:00:26,755] {taskinstance.py:896} INFO - Dependencies all met for <TaskInstance: assignment.task_one 2022-07-09T00:00:00+00:00 [queued]>
[2022-07-10 23:00:26,757] {taskinstance.py:1087} INFO - 
--------------------------------------------------------------------------------
[2022-07-10 23:00:26,759] {taskinstance.py:1088} INFO - Starting attempt 1 of 1
[2022-07-10 23:00:26,760] {taskinstance.py:1089} INFO - 
--------------------------------------------------------------------------------
[2022-07-10 23:00:26,803] {taskinstance.py:1107} INFO - Executing <Task(PythonOperator): task_one> on 2022-07-09T00:00:00+00:00
[2022-07-10 23:00:26,810] {standard_task_runner.py:52} INFO - Started process 2809 to run task
[2022-07-10 23:00:26,819] {standard_task_runner.py:76} INFO - Running: ['***', 'tasks', 'run', 'assignment', 'task_one', '2022-07-09T00:00:00+00:00', '--job-id', '3', '--pool', 'default_pool', '--raw', '--subdir', 'DAGS_FOLDER/assignment.py', '--cfg-path', '/tmp/tmp03904_ud', '--error-file', '/tmp/tmpc8v7w68d']
[2022-07-10 23:00:26,825] {standard_task_runner.py:77} INFO - Job 3: Subtask task_one
[2022-07-10 23:00:27,202] {logging_mixin.py:104} INFO - Running <TaskInstance: assignment.task_one 2022-07-09T00:00:00+00:00 [running]> on host c259055947c2
[2022-07-10 23:00:27,636] {taskinstance.py:1302} INFO - Exporting the following env vars:
AIRFLOW_CTX_DAG_OWNER=***
AIRFLOW_CTX_DAG_ID=assignment
AIRFLOW_CTX_TASK_ID=task_one
AIRFLOW_CTX_EXECUTION_DATE=2022-07-09T00:00:00+00:00
AIRFLOW_CTX_DAG_RUN_ID=scheduled__2022-07-09T00:00:00+00:00
[2022-07-10 23:00:27,642] {taskinstance.py:1501} ERROR - Task failed with exception
Traceback (most recent call last):
  File "/home/airflow/.local/lib/python3.6/site-packages/airflow/models/taskinstance.py", line 1157, in _run_raw_task
    self._prepare_and_execute_task_with_callbacks(context, task)
  File "/home/airflow/.local/lib/python3.6/site-packages/airflow/models/taskinstance.py", line 1331, in _prepare_and_execute_task_with_callbacks
    result = self._execute_task(context, task_copy)
  File "/home/airflow/.local/lib/python3.6/site-packages/airflow/models/taskinstance.py", line 1361, in _execute_task
    result = task_copy.execute(context=context)
  File "/home/airflow/.local/lib/python3.6/site-packages/airflow/operators/python.py", line 150, in execute
    return_value = self.execute_callable()
  File "/home/airflow/.local/lib/python3.6/site-packages/airflow/operators/python.py", line 161, in execute_callable
    return self.python_callable(*self.op_args, **self.op_kwargs)
  File "/opt/airflow/dags/assignment.py", line 28, in catalog
    with open('00_urls.txt') as u:
FileNotFoundError: [Errno 2] No such file or directory: '00_urls.txt'
[2022-07-10 23:00:27,659] {taskinstance.py:1551} INFO - Marking task as FAILED. dag_id=assignment, task_id=task_one, execution_date=20220709T000000, start_date=20220710T230026, end_date=20220710T230027
[2022-07-10 23:00:27,827] {local_task_job.py:151} INFO - Task exited with return code 1
